Traceback (most recent call last):
  File "/home/ahmadm79/Downloads/jon/Chatbot-WebApp/backend/venv/lib/python3.10/site-packages/sqlalchemy/engine/base.py", line 3371, in _wrap_pool_connect
    return fn()
  File "/home/ahmadm79/Downloads/jon/Chatbot-WebApp/backend/venv/lib/python3.10/site-packages/sqlalchemy/pool/base.py", line 327, in connect
    return _ConnectionFairy._checkout(self)
  File "/home/ahmadm79/Downloads/jon/Chatbot-WebApp/backend/venv/lib/python3.10/site-packages/sqlalchemy/pool/base.py", line 894, in _checkout
    fairy = _ConnectionRecord.checkout(pool)
  File "/home/ahmadm79/Downloads/jon/Chatbot-WebApp/backend/venv/lib/python3.10/site-packages/sqlalchemy/pool/base.py", line 493, in checkout
    rec = pool._do_get()
  File "/home/ahmadm79/Downloads/jon/Chatbot-WebApp/backend/venv/lib/python3.10/site-packages/sqlalchemy/pool/impl.py", line 256, in _do_get
    return self._create_connection()
  File "/home/ahmadm79/Downloads/jon/Chatbot-WebApp/backend/venv/lib/python3.10/site-packages/sqlalchemy/pool/base.py", line 273, in _create_connection
    return _ConnectionRecord(self)
  File "/home/ahmadm79/Downloads/jon/Chatbot-WebApp/backend/venv/lib/python3.10/site-packages/sqlalchemy/pool/base.py", line 388, in __init__
    self.__connect()
  File "/home/ahmadm79/Downloads/jon/Chatbot-WebApp/backend/venv/lib/python3.10/site-packages/sqlalchemy/pool/base.py", line 690, in __connect
    with util.safe_reraise():
  File "/home/ahmadm79/Downloads/jon/Chatbot-WebApp/backend/venv/lib/python3.10/site-packages/sqlalchemy/util/langhelpers.py", line 70, in __exit__
    compat.raise_(
  File "/home/ahmadm79/Downloads/jon/Chatbot-WebApp/backend/venv/lib/python3.10/site-packages/sqlalchemy/util/compat.py", line 211, in raise_
    raise exception
  File "/home/ahmadm79/Downloads/jon/Chatbot-WebApp/backend/venv/lib/python3.10/site-packages/sqlalchemy/pool/base.py", line 686, in __connect
    self.dbapi_connection = connection = pool._invoke_creator(self)
  File "/home/ahmadm79/Downloads/jon/Chatbot-WebApp/backend/venv/lib/python3.10/site-packages/sqlalchemy/engine/create.py", line 574, in connect
    return dialect.connect(*cargs, **cparams)
  File "/home/ahmadm79/Downloads/jon/Chatbot-WebApp/backend/venv/lib/python3.10/site-packages/sqlalchemy/engine/default.py", line 598, in connect
    return self.dbapi.connect(*cargs, **cparams)
sqlite3.OperationalError: unable to open database file

The above exception was the direct cause of the following exception:

Traceback (most recent call last):
  File "handle_request", line 83, in handle_request
    )
  File "/home/ahmadm79/Downloads/jon/Chatbot-WebApp/backend/venv/lib/python3.10/site-packages/rasa_sdk/endpoint.py", line 113, in webhook
    result = await executor.run(action_call)
  File "/home/ahmadm79/Downloads/jon/Chatbot-WebApp/backend/venv/lib/python3.10/site-packages/rasa_sdk/executor.py", line 399, in run
    action(dispatcher, tracker, domain)
  File "/home/ahmadm79/Downloads/jon/Chatbot-WebApp/chatbot/actions/infrastructure_actions.py", line 113, in run
    location = session.query(Infrastructure).filter_by(id=1).first()
  File "/home/ahmadm79/Downloads/jon/Chatbot-WebApp/backend/venv/lib/python3.10/site-packages/sqlalchemy/orm/query.py", line 2824, in first
    return self.limit(1)._iter().first()
  File "/home/ahmadm79/Downloads/jon/Chatbot-WebApp/backend/venv/lib/python3.10/site-packages/sqlalchemy/orm/query.py", line 2916, in _iter
    result = self.session.execute(
  File "/home/ahmadm79/Downloads/jon/Chatbot-WebApp/backend/venv/lib/python3.10/site-packages/sqlalchemy/orm/session.py", line 1716, in execute
    conn = self._connection_for_bind(bind)
  File "/home/ahmadm79/Downloads/jon/Chatbot-WebApp/backend/venv/lib/python3.10/site-packages/sqlalchemy/orm/session.py", line 1555, in _connection_for_bind
    return self._transaction._connection_for_bind(
  File "/home/ahmadm79/Downloads/jon/Chatbot-WebApp/backend/venv/lib/python3.10/site-packages/sqlalchemy/orm/session.py", line 750, in _connection_for_bind
    conn = bind.connect()
  File "/home/ahmadm79/Downloads/jon/Chatbot-WebApp/backend/venv/lib/python3.10/site-packages/sqlalchemy/engine/base.py", line 3325, in connect
    return self._connection_cls(self, close_with_result=close_with_result)
  File "/home/ahmadm79/Downloads/jon/Chatbot-WebApp/backend/venv/lib/python3.10/site-packages/sqlalchemy/engine/base.py", line 96, in __init__
    else engine.raw_connection()
  File "/home/ahmadm79/Downloads/jon/Chatbot-WebApp/backend/venv/lib/python3.10/site-packages/sqlalchemy/engine/base.py", line 3404, in raw_connection
    return self._wrap_pool_connect(self.pool.connect, _connection)
  File "/home/ahmadm79/Downloads/jon/Chatbot-WebApp/backend/venv/lib/python3.10/site-packages/sqlalchemy/engine/base.py", line 3374, in _wrap_pool_connect
    Connection._handle_dbapi_exception_noconnection(
  File "/home/ahmadm79/Downloads/jon/Chatbot-WebApp/backend/venv/lib/python3.10/site-packages/sqlalchemy/engine/base.py", line 2208, in _handle_dbapi_exception_noconnection
    util.raise_(
  File "/home/ahmadm79/Downloads/jon/Chatbot-WebApp/backend/venv/lib/python3.10/site-packages/sqlalchemy/util/compat.py", line 211, in raise_
    raise exception
  File "/home/ahmadm79/Downloads/jon/Chatbot-WebApp/backend/venv/lib/python3.10/site-packages/sqlalchemy/engine/base.py", line 3371, in _wrap_pool_connect
    return fn()
  File "/home/ahmadm79/Downloads/jon/Chatbot-WebApp/backend/venv/lib/python3.10/site-packages/sqlalchemy/pool/base.py", line 327, in connect
    return _ConnectionFairy._checkout(self)
  File "/home/ahmadm79/Downloads/jon/Chatbot-WebApp/backend/venv/lib/python3.10/site-packages/sqlalchemy/pool/base.py", line 894, in _checkout
    fairy = _ConnectionRecord.checkout(pool)
  File "/home/ahmadm79/Downloads/jon/Chatbot-WebApp/backend/venv/lib/python3.10/site-packages/sqlalchemy/pool/base.py", line 493, in checkout
    rec = pool._do_get()
  File "/home/ahmadm79/Downloads/jon/Chatbot-WebApp/backend/venv/lib/python3.10/site-packages/sqlalchemy/pool/impl.py", line 256, in _do_get
    return self._create_connection()
  File "/home/ahmadm79/Downloads/jon/Chatbot-WebApp/backend/venv/lib/python3.10/site-packages/sqlalchemy/pool/base.py", line 273, in _create_connection
    return _ConnectionRecord(self)
  File "/home/ahmadm79/Downloads/jon/Chatbot-WebApp/backend/venv/lib/python3.10/site-packages/sqlalchemy/pool/base.py", line 388, in __init__
    self.__connect()
  File "/home/ahmadm79/Downloads/jon/Chatbot-WebApp/backend/venv/lib/python3.10/site-packages/sqlalchemy/pool/base.py", line 690, in __connect
    with util.safe_reraise():
  File "/home/ahmadm79/Downloads/jon/Chatbot-WebApp/backend/venv/lib/python3.10/site-packages/sqlalchemy/util/langhelpers.py", line 70, in __exit__
    compat.raise_(
  File "/home/ahmadm79/Downloads/jon/Chatbot-WebApp/backend/venv/lib/python3.10/site-packages/sqlalchemy/util/compat.py", line 211, in raise_
    raise exception
  File "/home/ahmadm79/Downloads/jon/Chatbot-WebApp/backend/venv/lib/python3.10/site-packages/sqlalchemy/pool/base.py", line 686, in __connect
    self.dbapi_connection = connection = pool._invoke_creator(self)
  File "/home/ahmadm79/Downloads/jon/Chatbot-WebApp/backend/venv/lib/python3.10/site-packages/sqlalchemy/engine/create.py", line 574, in connect
    return dialect.connect(*cargs, **cparams)
  File "/home/ahmadm79/Downloads/jon/Chatbot-WebApp/backend/venv/lib/python3.10/site-packages/sqlalchemy/engine/default.py", line 598, in connect
    return self.dbapi.connect(*cargs, **cparams)
sqlalchemy.exc.OperationalError: (sqlite3.OperationalError) unable to open database file
(Background on this error at: https://sqlalche.me/e/14/e3q8)
